Workbook
Name Annual_depreciation: '2a), 4) Inputs'!$E$20
Name Annual_salary_base_costs: '2a), 4) Inputs'!$E$37
Name Annual_salary_costs: '2a), 4) Inputs'!$E$36
Name Bank_rate: '2a), 4) Inputs'!$B$24
Name Capacity_per_trip: '2a), 4) Inputs'!$B$15
Name Carbon_offset: '2a), 4) Inputs'!$B$37
Name Carbon_offset_rate: '2a), 4) Inputs'!$B$26
Name Corporate_tax_rate: '2a), 4) Inputs'!$B$27
Name Daily_demand_LNG_Y2: '2b) Schedules'!$R$25
Name Days_in_year: '2a), 4) Inputs'!$B$6
Name Deferred_year: '2a), 4) Inputs'!$B$10
Name Depreciation_expense_Y1: '2a), 4) Inputs'!$E$20
Name Development_cost: '2a), 4) Inputs'!$B$18
Name Employee_contribution: '2a), 4) Inputs'!$E$39
Name Employer_contribution: '2a), 4) Inputs'!$E$40
Name First_year: '2a), 4) Inputs'!$B$5
Name Gas_demand_rate: '2a), 4) Inputs'!$B$25
Name General_maintenance: '2a), 4) Inputs'!$E$32
Name Heavy_fuel_oil: '2b) Schedules'!$R$26
Name Increment: '2a), 4) Inputs'!$B$9
Name Inflation_rate: '2a), 4) Inputs'!$B$23
Name Insurance_expense: '2a), 4) Inputs'!$E$29
Name Minimum_balance: '2a), 4) Inputs'!$B$19
Name Months_in_year: '2a), 4) Inputs'!$B$8
Name NPV__Rate_of_Financing: '1) NPV Comparison'!$B$15
Name NPV_Development_Time__Yr: '1) NPV Comparison'!$B$7
Name NPV_First_Year: '1) NPV Comparison'!$K$37
Name NPV_Gas_demand_rate: '1) NPV Comparison'!$B$16
Name NPV_Half_Year_Increment: '1) NPV Comparison'!$B$10
Name NPV_Increment: '1) NPV Comparison'!$B$8
Name NPV_LNG_Purchase_cost: '1) NPV Comparison'!$B$45
Name NPV_LNG_Selling_price: '1) NPV Comparison'!$B$46
Name NPV_Months_in_Year: '1) NPV Comparison'!$B$5
Name NPV_Rate_of_Inflation: '1) NPV Comparison'!$B$13
Name NPV_Rate_of_Inflation__Carbon_Offsets: '1) NPV Comparison'!$B$14
Name NPV_Weeks_in_Year: '1) NPV Comparison'!$B$6
Name NPV_Years_of_Operation: '1) NPV Comparison'!$B$9
Name Operating_expense: '2a), 4) Inputs'!$E$31
Name Pipeline_Carbon_Offsets__Paid_monthly_on_15th: '1) NPV Comparison'!$B$36
Name Pipeline_Development_cost: '1) NPV Comparison'!$B$19
Name Pipeline_Increment: '1) NPV Comparison'!$B$8
Name Pipeline_Purchase_Price_Y2: '1) NPV Comparison'!$B$25
Name Pipeline_Rate_of_increase_in_demand: '1) NPV Comparison'!$B$20
Name Pipeline_Sale_Price_Y2: '1) NPV Comparison'!$B$26
Name Pipeline_Sales_Y2: '1) NPV Comparison'!$B$24
Name Pipeline_Salvage_Value_Y31: '1) NPV Comparison'!$B$21
Name Pipeline_Total_annual_cost_Y2: '1) NPV Comparison'!$B$33
Name Port_Damage_Expense: '2a), 4) Inputs'!$B$42
Name Port_fee: '2a), 4) Inputs'!$E$30
Name Price_per_ton: '2a), 4) Inputs'!$B$32
Name Purchase_cost_LNG: '2a), 4) Inputs'!$E$25
Name Quantity_demand_Y1: '2a), 4) Inputs'!$E$6
Name Quantity_demand_Y2: '2a), 4) Inputs'!$E$24
Name Quantity_demanded_Y1: '2a), 4) Inputs'!$E$6
Name Salvage_value: '2a), 4) Inputs'!$B$17
Name Selling_price_LNG_Y2: '2a), 4) Inputs'!$E$26
Name Stores_and_lubricants: '2a), 4) Inputs'!$E$33
Name Tanker_Daily_demand_Y2: '1) NPV Comparison'!$B$44
Name Tanker_Development_Cost: '1) NPV Comparison'!$B$39
Name Tanker_Quantity_demanded_Y2: '1) NPV Comparison'!$B$43

Sheet Cover Page
K2: Course Ref | L2: BUSI 414
K3: Course Name | L3: Data Visualization and Business Analytics
K4: Team | L4: Ag Accounting & Consulting
K5: Students | L5: G. Bennett 10134492
L6: E. Dizon 47881479
L7: V. Domet 77545341
L8: U. Kos 83027870
L9: T. Lee 39546149
C10: DATA MODEL: QATAR ENERGY CASE
C13: Business Proposition: We will operate a single Q-Max Tanker to supply Qatari Natural Gas to Bahrain over a 30-year contract period. We hold the exclusive rights to sell Qatari Natural Gas and its liquid form, LNG, to other countries (1). We will be the exclusive supplier to the country of Bahrain (2). Bahrain is a neighbouring nation separated by only 80km of sea. The Q-Max Tanker can deliver LNG often and without major risks (3). The demand for LNG will increase steadily over the 30-year contract period. Our Q-Max tanker will supply more than enough LNG for this growing demand (4).
C16: Executive Summary: The business plan appears viable. QatarEnergy will need approximately $260 million of financing. The Q-Max Tanker will sell LNG at $28 per cubic meter in the first year of operation, which will be achieved with a loan from the National Bank of Qatar. We have projected that in the first month of the first year of operations we will have $1.734 million in cumulative net income, where payment will be made daily, one day in arrears by Bahrain. Given the current market and economic conditions, we estimate that undertaking this project would return a net present value of $1.456 billion after startup and 30 consecutive years of operation.

Sheet 1) NPV Comparison
A1: QatarEnergy
A2: NPV Comparison - Pipeline vs. Tanker
A4: Time & Date | D4: Round Trips Required | G4: Cash Flows - Pipeline | J4: Cash Flows - Tanker | M4: Color Key
A5: NPV Months in Year | B5: 12 | D5: Period | E5: # of Trips | G5: End of year | H5: Gross margin | J5: End of year | K5: Gross margin | M5: Black = scaffolding, calculated values (do not overwrite)
A6: NPV Weeks in Year | B6: 52 | D6: 2 | E6: 109 | G6: 1 | H6: =-Pipeline_Development_cost -> -520000000 | J6: 1 | K6: =-Tanker_Development_Cost -> -250000000 | M6: Pink = calculated value from other sheet (do not overwrite)
A7: NPV Development Time (Yr) | B7: 1 | D7: 3 | E7: 110 | G7: 2 | H7: =Pipeline_Sales_Y2*(Increment+Pipeline_Rate_of_increase_in_demand)^(G7-NPV_Increment)*(Pipeline_Sale_Price_Y2-Pipeline_Purchase_Price_Y2)*(Increment+NPV_Rate_of_Inflation)^(G7-NPV_Increment)-Pipeline_Total_annual_cost_Y2*(Increment+NPV_Rate_of_Inflation)^(G7-NPV_Increment)-Pipeline_Carbon_Offsets__Paid_monthly_on_15th*(Increment+NPV_Rate_of_Inflation__Carbon_Offsets)^(G7-NPV_Increment)-D68 -> 50626915 | J7: 2 | K7: =Tanker_Quantity_demanded_Y2*(Increment+NPV_Gas_demand_rate)^(J7-NPV_Increment)*(NPV_LNG_Selling_price-NPV_LNG_Purchase_cost)*(Increment+NPV_Rate_of_Inflation)^(J7-NPV_Increment)-$B$56*(Increment+NPV_Rate_of_Inflation__Carbon_Offsets)^(J7-NPV_Increment)-$B$63*E6*(Increment+NPV_Rate_of_Inflation)^(J7-NPV_Increment)-Tanker_Total_Annual_Cost_Y2*(Increment+NPV_Rate_of_Inflation)^(J7-NPV_Increment)-D102 -> 83599245 | M7: Red = external data (editable)
A8: NPV Increment | B8: 2 | D8: 4 | E8: 111 | G8: 3 | H8: =Pipeline_Sales_Y2*(Increment+Pipeline_Rate_of_increase_in_demand)^(G8-NPV_Increment)*(Pipeline_Sale_Price_Y2-Pipeline_Purchase_Price_Y2)*(Increment+NPV_Rate_of_Inflation)^(G8-NPV_Increment)-Pipeline_Total_annual_cost_Y2*(Increment+NPV_Rate_of_Inflation)^(G8-NPV_Increment)-Pipeline_Carbon_Offsets__Paid_monthly_on_15th*(Increment+NPV_Rate_of_Inflation__Carbon_Offsets)^(G8-NPV_Increment)-D69 -> 52344865 | J8: 3 | K8: =Tanker_Quantity_demanded_Y2*(Increment+NPV_Gas_demand_rate)^(J8-NPV_Increment)*(NPV_LNG_Selling_price-NPV_LNG_Purchase_cost)*(Increment+NPV_Rate_of_Inflation)^(J8-NPV_Increment)-$B$56*(Increment+NPV_Rate_of_Inflation__Carbon_Offsets)^(J8-NPV_Increment)-$B$63*E7*(Increment+NPV_Rate_of_Inflation)^(J8-NPV_Increment)-Tanker_Total_Annual_Cost_Y2*(Increment+NPV_Rate_of_Inflation)^(J8-NPV_Increment)-D103 -> 84871925 | M8: Black on Blue = owner's decision
A9: NPV Years of Operation | B9: 30 | D9: 5 | E9: 111 | G9: 4 | H9: =Pipeline_Sales_Y2*(Increment+Pipeline_Rate_of_increase_in_demand)^(G9-NPV_Increment)*(Pipeline_Sale_Price_Y2-Pipeline_Purchase_Price_Y2)*(Increment+NPV_Rate_of_Inflation)^(G9-NPV_Increment)-Pipeline_Total_annual_cost_Y2*(Increment+NPV_Rate_of_Inflation)^(G9-NPV_Increment)-Pipeline_Carbon_Offsets__Paid_monthly_on_15th*(Increment+NPV_Rate_of_Inflation__Carbon_Offsets)^(G9-NPV_Increment)-D70 -> 54098228 | J9: 4 | K9: =Tanker_Quantity_demanded_Y2*(Increment+NPV_Gas_demand_rate)^(J9-NPV_Increment)*(NPV_LNG_Selling_price-NPV_LNG_Purchase_cost)*(Increment+NPV_Rate_of_Inflation)^(J9-NPV_Increment)-$B$56*(Increment+NPV_Rate_of_Inflation__Carbon_Offsets)^(J9-NPV_Increment)-$B$63*E8*(Increment+NPV_Rate_of_Inflation)^(J9-NPV_Increment)-Tanker_Total_Annual_Cost_Y2*(Increment+NPV_Rate_of_Inflation)^(J9-NPV_Increment)-D104 -> 86146028 | N9: Gray shade (stay out!)
A10: NPV Half Year Increment | B10: 6 | D10: 6 | E10: 112 | G10: 5 | H10: =Pipeline_Sales_Y2*(Increment+Pipeline_Rate_of_increase_in_demand)^(G10-NPV_Increment)*(Pipeline_Sale_Price_Y2-Pipeline_Purchase_Price_Y2)*(Increment+NPV_Rate_of_Inflation)^(G10-NPV_Increment)-Pipeline_Total_annual_cost_Y2*(Increment+NPV_Rate_of_Inflation)^(G10-NPV_Increment)-Pipeline_Carbon_Offsets__Paid_monthly_on_15th*(Increment+NPV_Rate_of_Inflation__Carbon_Offsets)^(G10-NPV_Increment)-D71 -> 55887713 | J10: 5 | K10: =Tanker_Quantity_demanded_Y2*(Increment+NPV_Gas_demand_rate)^(J10-NPV_Increment)*(NPV_LNG_Selling_price-NPV_LNG_Purchase_cost)*(Increment+NPV_Rate_of_Inflation)^(J10-NPV_Increment)-$B$56*(Increment+NPV_Rate_of_Inflation__Carbon_Offsets)^(J10-NPV_Increment)-$B$63*E9*(Increment+NPV_Rate_of_Inflation)^(J10-NPV_Increment)-Tanker_Total_Annual_Cost_Y2*(Increment+NPV_Rate_of_Inflation)^(J10-NPV_Increment)-D105 -> 87702070
D11: 7 | E11: 112 | G11: 6 | H11: =Pipeline_Sales_Y2*(Increment+Pipeline_Rate_of_increase_in_demand)^(G11-NPV_Increment)*(Pipeline_Sale_Price_Y2-Pipeline_Purchase_Price_Y2)*(Increment+NPV_Rate_of_Inflation)^(G11-NPV_Increment)-Pipeline_Total_annual_cost_Y2*(Increment+NPV_Rate_of_Inflation)^(G11-NPV_Increment)-Pipeline_Carbon_Offsets__Paid_monthly_on_15th*(Increment+NPV_Rate_of_Inflation__Carbon_Offsets)^(G11-NPV_Increment)-D72 -> 57714045 | J11: 6 | K11: =Tanker_Quantity_demanded_Y2*(Increment+NPV_Gas_demand_rate)^(J11-NPV_Increment)*(NPV_LNG_Selling_price-NPV_LNG_Purchase_cost)*(Increment+NPV_Rate_of_Inflation)^(J11-NPV_Increment)-$B$56*(Increment+NPV_Rate_of_Inflation__Carbon_Offsets)^(J11-NPV_Increment)-$B$63*E10*(Increment+NPV_Rate_of_Inflation)^(J11-NPV_Increment)-Tanker_Total_Annual_Cost_Y2*(Increment+NPV_Rate_of_Inflation)^(J11-NPV_Increment)-D106 -> 88980493
A12: Rates | D12: 8 | E12: 113 | G12: 7 | H12: =Pipeline_Sales_Y2*(Increment+Pipeline_Rate_of_increase_in_demand)^(G12-NPV_Increment)*(Pipeline_Sale_Price_Y2-Pipeline_Purchase_Price_Y2)*(Increment+NPV_Rate_of_Inflation)^(G12-NPV_Increment)-Pipeline_Total_annual_cost_Y2*(Increment+NPV_Rate_of_Inflation)^(G12-NPV_Increment)-Pipeline_Carbon_Offsets__Paid_monthly_on_15th*(Increment+NPV_Rate_of_Inflation__Carbon_Offsets)^(G12-NPV_Increment)-D73 -> 59577963 | J12: 7 | K12: =Tanker_Quantity_demanded_Y2*(Increment+NPV_Gas_demand_rate)^(J12-NPV_Increment)*(NPV_LNG_Selling_price-NPV_LNG_Purchase_cost)*(Increment+NPV_Rate_of_Inflation)^(J12-NPV_Increment)-$B$56*(Increment+NPV_Rate_of_Inflation__Carbon_Offsets)^(J12-NPV_Increment)-$B$63*E11*(Increment+NPV_Rate_of_Inflation)^(J12-NPV_Increment)-Tanker_Total_Annual_Cost_Y2*(Increment+NPV_Rate_of_Inflation)^(J12-NPV_Increment)-D107 -> 90547464
A13: NPV Rate of Inflation | B13: 0.015 | D13: 9 | E13: 113 | G13: 8 | H13: =Pipeline_Sales_Y2*(Increment+Pipeline_Rate_of_increase_in_demand)^(G13-NPV_Increment)*(Pipeline_Sale_Price_Y2-Pipeline_Purchase_Price_Y2)*(Increment+NPV_Rate_of_Inflation)^(G13-NPV_Increment)-Pipeline_Total_annual_cost_Y2*(Increment+NPV_Rate_of_Inflation)^(G13-NPV_Increment)-Pipeline_Carbon_Offsets__Paid_monthly_on_15th*(Increment+NPV_Rate_of_Inflation__Carbon_Offsets)^(G13-NPV_Increment)-D74 -> 61480219 | J13: 8 | K13: =Tanker_Quantity_demanded_Y2*(Increment+NPV_Gas_demand_rate)^(J13-NPV_Increment)*(NPV_LNG_Selling_price-NPV_LNG_Purchase_cost)*(Increment+NPV_Rate_of_Inflation)^(J13-NPV_Increment)-$B$56*(Increment+NPV_Rate_of_Inflation__Carbon_Offsets)^(J13-NPV_Increment)-$B$63*E12*(Increment+NPV_Rate_of_Inflation)^(J13-NPV_Increment)-Tanker_Total_Annual_Cost_Y2*(Increment+NPV_Rate_of_Inflation)^(J13-NPV_Increment)-D108 -> 91826428
A14: NPV Rate of Inflation (Carbon Offsets) | B14: 0.039 | D14: 10 | E14: 114 | G14: 9 | H14: =Pipeline_Sales_Y2*(Increment+Pipeline_Rate_of_increase_in_demand)^(G14-NPV_Increment)*(Pipeline_Sale_Price_Y2-Pipeline_Purchase_Price_Y2)*(Increment+NPV_Rate_of_Inflation)^(G14-NPV_Increment)-Pipeline_Total_annual_cost_Y2*(Increment+NPV_Rate_of_Inflation)^(G14-NPV_Increment)-Pipeline_Carbon_Offsets__Paid_monthly_on_15th*(Increment+NPV_Rate_of_Inflation__Carbon_Offsets)^(G14-NPV_Increment)-D75 -> 63421579 | J14: 9 | K14: =Tanker_Quantity_demanded_Y2*(Increment+NPV_Gas_demand_rate)^(J14-NPV_Increment)*(NPV_LNG_Selling_price-NPV_LNG_Purchase_cost)*(Increment+NPV_Rate_of_Inflation)^(J14-NPV_Increment)-$B$56*(Increment+NPV_Rate_of_Inflation__Carbon_Offsets)^(J14-NPV_Increment)-$B$63*E13*(Increment+NPV_Rate_of_Inflation)^(J14-NPV_Increment)-Tanker_Total_Annual_Cost_Y2*(Increment+NPV_Rate_of_Inflation)^(J14-NPV_Increment)-D109 -> 93400570
A15: NPV Rate of Financing | B15: 0.04 | D15: 11 | E15: 114 | G15: 10 | H15: =Pipeline_Sales_Y2*(Increment+Pipeline_Rate_of_increase_in_demand)^(G15-NPV_Increment)*(Pipeline_Sale_Price_Y2-Pipeline_Purchase_Price_Y2)*(Increment+NPV_Rate_of_Inflation)^(G15-NPV_Increment)-Pipeline_Total_annual_cost_Y2*(Increment+NPV_Rate_of_Inflation)^(G15-NPV_Increment)-Pipeline_Carbon_Offsets__Paid_monthly_on_15th*(Increment+NPV_Rate_of_Inflation__Carbon_Offsets)^(G15-NPV_Increment)-D76 -> 65402826 | J15: 10 | K15: =Tanker_Quantity_demanded_Y2*(Increment+NPV_Gas_demand_rate)^(J15-NPV_Increment)*(NPV_LNG_Selling_price-NPV_LNG_Purchase_cost)*(Increment+NPV_Rate_of_Inflation)^(J15-NPV_Increment)-$B$56*(Increment+NPV_Rate_of_Inflation__Carbon_Offsets)^(J15-NPV_Increment)-$B$63*E14*(Increment+NPV_Rate_of_Inflation)^(J15-NPV_Increment)-Tanker_Total_Annual_Cost_Y2*(Increment+NPV_Rate_of_Inflation)^(J15-NPV_Increment)-D110 -> 94675816
A16: NPV Gas Demand Rate | B16: 0.005 | D16: 12 | E16: 115 | G16: 11 | H16: =Pipeline_Sales_Y2*(Increment+Pipeline_Rate_of_increase_in_demand)^(G16-NPV_Increment)*(Pipeline_Sale_Price_Y2-Pipeline_Purchase_Price_Y2)*(Increment+NPV_Rate_of_Inflation)^(G16-NPV_Increment)-Pipeline_Total_annual_cost_Y2*(Increment+NPV_Rate_of_Inflation)^(G16-NPV_Increment)-Pipeline_Carbon_Offsets__Paid_monthly_on_15th*(Increment+NPV_Rate_of_Inflation__Carbon_Offsets)^(G16-NPV_Increment)-D77 -> 67424756 | J16: 11 | K16: =Tanker_Quantity_demanded_Y2*(Increment+NPV_Gas_demand_rate)^(J16-NPV_Increment)*(NPV_LNG_Selling_price-NPV_LNG_Purchase_cost)*(Increment+NPV_Rate_of_Inflation)^(J16-NPV_Increment)-$B$56*(Increment+NPV_Rate_of_Inflation__Carbon_Offsets)^(J16-NPV_Increment)-$B$63*E15*(Increment+NPV_Rate_of_Inflation)^(J16-NPV_Increment)-Tanker_Total_Annual_Cost_Y2*(Increment+NPV_Rate_of_Inflation)^(J16-NPV_Increment)-D111 -> 96252881
D17: 13 | E17: 116 | G17: 12 | H17: =Pipeline_Sales_Y2*(Increment+Pipeline_Rate_of_increase_in_demand)^(G17-NPV_Increment)*(Pipeline_Sale_Price_Y2-Pipeline_Purchase_Price_Y2)*(Increment+NPV_Rate_of_Inflation)^(G17-NPV_Increment)-Pipeline_Total_annual_cost_Y2*(Increment+NPV_Rate_of_Inflation)^(G17-NPV_Increment)-Pipeline_Carbon_Offsets__Paid_monthly_on_15th*(Increment+NPV_Rate_of_Inflation__Carbon_Offsets)^(G17-NPV_Increment)-D78 -> 69488181 | J17: 12 | K17: =Tanker_Quantity_demanded_Y2*(Increment+NPV_Gas_demand_rate)^(J17-NPV_Increment)*(NPV_LNG_Selling_price-NPV_LNG_Purchase_cost)*(Increment+NPV_Rate_of_Inflation)^(J17-NPV_Increment)-$B$56*(Increment+NPV_Rate_of_Inflation__Carbon_Offsets)^(J17-NPV_Increment)-$B$63*E16*(Increment+NPV_Rate_of_Inflation)^(J17-NPV_Increment)-Tanker_Total_Annual_Cost_Y2*(Increment+NPV_Rate_of_Inflation)^(J17-NPV_Increment)-D112 -> 97519632
A18: Pipeline Inputs | D18: 14 | E18: 116 | G18: 13 | H18: =Pipeline_Sales_Y2*(Increment+Pipeline_Rate_of_increase_in_demand)^(G18-NPV_Increment)*(Pipeline_Sale_Price_Y2-Pipeline_Purchase_Price_Y2)*(Increment+NPV_Rate_of_Inflation)^(G18-NPV_Increment)-Pipeline_Total_annual_cost_Y2*(Increment+NPV_Rate_of_Inflation)^(G18-NPV_Increment)-Pipeline_Carbon_Offsets__Paid_monthly_on_15th*(Increment+NPV_Rate_of_Inflation__Carbon_Offsets)^(G18-NPV_Increment)-D79 -> 71593928 | J18: 13 | K18: =Tanker_Quantity_demanded_Y2*(Increment+NPV_Gas_demand_rate)^(J18-NPV_Increment)*(NPV_LNG_Selling_price-NPV_LNG_Purchase_cost)*(Increment+NPV_Rate_of_Inflation)^(J18-NPV_Increment)-$B$56*(Increment+NPV_Rate_of_Inflation__Carbon_Offsets)^(J18-NPV_Increment)-$B$63*E17*(Increment+NPV_Rate_of_Inflation)^(J18-NPV_Increment)-Tanker_Total_Annual_Cost_Y2*(Increment+NPV_Rate_of_Inflation)^(J18-NPV_Increment)-D113 -> 98777825
A19: Pipeline Development Cost | B19: 520000000 | D19: 15 | E19: 117 | G19: 14 | H19: =Pipeline_Sales_Y2*(Increment+Pipeline_Rate_of_increase_in_demand)^(G19-NPV_Increment)*(Pipeline_Sale_Price_Y2-Pipeline_Purchase_Price_Y2)*(Increment+NPV_Rate_of_Inflation)^(G19-NPV_Increment)-Pipeline_Total_annual_cost_Y2*(Increment+NPV_Rate_of_Inflation)^(G19-NPV_Increment)-Pipeline_Carbon_Offsets__Paid_monthly_on_15th*(Increment+NPV_Rate_of_Inflation__Carbon_Offsets)^(G19-NPV_Increment)-D80 -> 73742840 | J19: 14 | K19: =Tanker_Quantity_demanded_Y2*(Increment+NPV_Gas_demand_rate)^(J19-NPV_Increment)*(NPV_LNG_Selling_price-NPV_LNG_Purchase_cost)*(Increment+NPV_Rate_of_Inflation)^(J19-NPV_Increment)-$B$56*(Increment+NPV_Rate_of_Inflation__Carbon_Offsets)^(J19-NPV_Increment)-$B$63*E18*(Increment+NPV_Rate_of_Inflation)^(J19-NPV_Increment)-Tanker_Total_Annual_Cost_Y2*(Increment+NPV_Rate_of_Inflation)^(J19-NPV_Increment)-D114 -> 1.0034774e+08
A20: Pipeline Rate of Increase in Demand | B20: 0.005 | D20: 16 | E20: 117 | G20: 15 | H20: =Pipeline_Sales_Y2*(Increment+Pipeline_Rate_of_increase_in_demand)^(G20-NPV_Increment)*(Pipeline_Sale_Price_Y2-Pipeline_Purchase_Price_Y2)*(Increment+NPV_Rate_of_Inflation)^(G20-NPV_Increment)-Pipeline_Total_annual_cost_Y2*(Increment+NPV_Rate_of_Inflation)^(G20-NPV_Increment)-Pipeline_Carbon_Offsets__Paid_monthly_on_15th*(Increment+NPV_Rate_of_Inflation__Carbon_Offsets)^(G20-NPV_Increment)-D81 -> 75935777 | J20: 15 | K20: =Tanker_Quantity_demanded_Y2*(Increment+NPV_Gas_demand_rate)^(J20-NPV_Increment)*(NPV_LNG_Selling_price-NPV_LNG_Purchase_cost)*(Increment+NPV_Rate_of_Inflation)^(J20-NPV_Increment)-$B$56*(Increment+NPV_Rate_of_Inflation__Carbon_Offsets)^(J20-NPV_Increment)-$B$63*E19*(Increment+NPV_Rate_of_Inflation)^(J20-NPV_Increment)-Tanker_Total_Annual_Cost_Y2*(Increment+NPV_Rate_of_Inflation)^(J20-NPV_Increment)-D115 -> 1.0158912e+08
A21: Pipeline Salvage Value, Y31 | B21: 15000000 | D21: 17 | E21: 118 | G21: 16 | H21: =Pipeline_Sales_Y2*(Increment+Pipeline_Rate_of_increase_in_demand)^(G21-NPV_Increment)*(Pipeline_Sale_Price_Y2-Pipeline_Purchase_Price_Y2)*(Increment+NPV_Rate_of_Inflation)^(G21-NPV_Increment)-Pipeline_Total_annual_cost_Y2*(Increment+NPV_Rate_of_Inflation)^(G21-NPV_Increment)-Pipeline_Carbon_Offsets__Paid_monthly_on_15th*(Increment+NPV_Rate_of_Inflation__Carbon_Offsets)^(G21-NPV_Increment)-D82 -> 78173613 | J21: 16 | K21: =Tanker_Quantity_demanded_Y2*(Increment+NPV_Gas_demand_rate)^(J21-NPV_Increment)*(NPV_LNG_Selling_price-NPV_LNG_Purchase_cost)*(Increment+NPV_Rate_of_Inflation)^(J21-NPV_Increment)-$B$56*(Increment+NPV_Rate_of_Inflation__Carbon_Offsets)^(J21-NPV_Increment)-$B$63*E20*(Increment+NPV_Rate_of_Inflation)^(J21-NPV_Increment)-Tanker_Total_Annual_Cost_Y2*(Increment+NPV_Rate_of_Inflation)^(J21-NPV_Increment)-D116 -> 1.031488e+08
D22: 18 | E22: 119 | G22: 17 | H22: =Pipeline_Sales_Y2*(Increment+Pipeline_Rate_of_increase_in_demand)^(G22-NPV_Increment)*(Pipeline_Sale_Price_Y2-Pipeline_Purchase_Price_Y2)*(Increment+NPV_Rate_of_Inflation)^(G22-NPV_Increment)-Pipeline_Total_annual_cost_Y2*(Increment+NPV_Rate_of_Inflation)^(G22-NPV_Increment)-Pipeline_Carbon_Offsets__Paid_monthly_on_15th*(Increment+NPV_Rate_of_Inflation__Carbon_Offsets)^(G22-NPV_Increment)-D83 -> 80457242 | J22: 17 | K22: =Tanker_Quantity_demanded_Y2*(Increment+NPV_Gas_demand_rate)^(J22-NPV_Increment)*(NPV_LNG_Selling_price-NPV_LNG_Purchase_cost)*(Increment+NPV_Rate_of_Inflation)^(J22-NPV_Increment)-$B$56*(Increment+NPV_Rate_of_Inflation__Carbon_Offsets)^(J22-NPV_Increment)-$B$63*E21*(Increment+NPV_Rate_of_Inflation)^(J22-NPV_Increment)-Tanker_Total_Annual_Cost_Y2*(Increment+NPV_Rate_of_Inflation)^(J22-NPV_Increment)-D117 -> 1.0436705e+08
A23: Revenues (Oil) | D23: 19 | E23: 119 | G23: 18 | H23: =Pipeline_Sales_Y2*(Increment+Pipeline_Rate_of_increase_in_demand)^(G23-NPV_Increment)*(Pipeline_Sale_Price_Y2-Pipeline_Purchase_Price_Y2)*(Increment+NPV_Rate_of_Inflation)^(G23-NPV_Increment)-Pipeline_Total_annual_cost_Y2*(Increment+NPV_Rate_of_Inflation)^(G23-NPV_Increment)-Pipeline_Carbon_Offsets__Paid_monthly_on_15th*(Increment+NPV_Rate_of_Inflation__Carbon_Offsets)^(G23-NPV_Increment)-D84 -> 82787572 | J23: 18 | K23: =Tanker_Quantity_demanded_Y2*(Increment+NPV_Gas_demand_rate)^(J23-NPV_Increment)*(NPV_LNG_Selling_price-NPV_LNG_Purchase_cost)*(Increment+NPV_Rate_of_Inflation)^(J23-NPV_Increment)-$B$56*(Increment+NPV_Rate_of_Inflation__Carbon_Offsets)^(J23-NPV_Increment)-$B$63*E22*(Increment+NPV_Rate_of_Inflation)^(J23-NPV_Increment)-Tanker_Total_Annual_Cost_Y2*(Increment+NPV_Rate_of_Inflation)^(J23-NPV_Increment)-D118 -> 1.0556862e+08
A24: Pipeline Sales, Y2 | B24: 17000000000 | D24: 20 | E24: 120 | G24: 19 | H24: =Pipeline_Sales_Y2*(Increment+Pipeline_Rate_of_increase_in_demand)^(G24-NPV_Increment)*(Pipeline_Sale_Price_Y2-Pipeline_Purchase_Price_Y2)*(Increment+NPV_Rate_of_Inflation)^(G24-NPV_Increment)-Pipeline_Total_annual_cost_Y2*(Increment+NPV_Rate_of_Inflation)^(G24-NPV_Increment)-Pipeline_Carbon_Offsets__Paid_monthly_on_15th*(Increment+NPV_Rate_of_Inflation__Carbon_Offsets)^(G24-NPV_Increment)-D85 -> 85165529 | J24: 19 | K24: =Tanker_Quantity_demanded_Y2*(Increment+NPV_Gas_demand_rate)^(J24-NPV_Increment)*(NPV_LNG_Selling_price-NPV_LNG_Purchase_cost)*(Increment+NPV_Rate_of_Inflation)^(J24-NPV_Increment)-$B$56*(Increment+NPV_Rate_of_Inflation__Carbon_Offsets)^(J24-NPV_Increment)-$B$63*E23*(Increment+NPV_Rate_of_Inflation)^(J24-NPV_Increment)-Tanker_Total_Annual_Cost_Y2*(Increment+NPV_Rate_of_Inflation)^(J24-NPV_Increment)-D119 -> 1.0709823e+08
A25: Pipeline Purchase Price, Y2 | B25: 0.046 | D25: 21 | E25: 120 | G25: 20 | H25: =Pipeline_Sales_Y2*(Increment+Pipeline_Rate_of_increase_in_demand)^(G25-NPV_Increment)*(Pipeline_Sale_Price_Y2-Pipeline_Purchase_Price_Y2)*(Increment+NPV_Rate_of_Inflation)^(G25-NPV_Increment)-Pipeline_Total_annual_cost_Y2*(Increment+NPV_Rate_of_Inflation)^(G25-NPV_Increment)-Pipeline_Carbon_Offsets__Paid_monthly_on_15th*(Increment+NPV_Rate_of_Inflation__Carbon_Offsets)^(G25-NPV_Increment)-D86 -> 87592056 | J25: 20 | K25: =Tanker_Quantity_demanded_Y2*(Increment+NPV_Gas_demand_rate)^(J25-NPV_Increment)*(NPV_LNG_Selling_price-NPV_LNG_Purchase_cost)*(Increment+NPV_Rate_of_Inflation)^(J25-NPV_Increment)-$B$56*(Increment+NPV_Rate_of_Inflation__Carbon_Offsets)^(J25-NPV_Increment)-$B$63*E24*(Increment+NPV_Rate_of_Inflation)^(J25-NPV_Increment)-Tanker_Total_Annual_Cost_Y2*(Increment+NPV_Rate_of_Inflation)^(J25-NPV_Increment)-D120 -> 1.0826579e+08
A26: Pipeline Sale Price, Y2 | B26: 0.052 | D26: 22 | E26: 121 | G26: 21 | H26: =Pipeline_Sales_Y2*(Increment+Pipeline_Rate_of_increase_in_demand)^(G26-NPV_Increment)*(Pipeline_Sale_Price_Y2-Pipeline_Purchase_Price_Y2)*(Increment+NPV_Rate_of_Inflation)^(G26-NPV_Increment)-Pipeline_Total_annual_cost_Y2*(Increment+NPV_Rate_of_Inflation)^(G26-NPV_Increment)-Pipeline_Carbon_Offsets__Paid_monthly_on_15th*(Increment+NPV_Rate_of_Inflation__Carbon_Offsets)^(G26-NPV_Increment)-D87 -> 90068116 | J26: 21 | K26: =Tanker_Quantity_demanded_Y2*(Increment+NPV_Gas_demand_rate)^(J26-NPV_Increment)*(NPV_LNG_Selling_price-NPV_LNG_Purchase_cost)*(Increment+NPV_Rate_of_Inflation)^(J26-NPV_Increment)-$B$56*(Increment+NPV_Rate_of_Inflation__Carbon_Offsets)^(J26-NPV_Increment)-$B$63*E25*(Increment+NPV_Rate_of_Inflation)^(J26-NPV_Increment)-Tanker_Total_Annual_Cost_Y2*(Increment+NPV_Rate_of_Inflation)^(J26-NPV_Increment)-D121 -> 1.0976778e+08
D27: 23 | E27: 121 | G27: 22 | H27: =Pipeline_Sales_Y2*(Increment+Pipeline_Rate_of_increase_in_demand)^(G27-NPV_Increment)*(Pipeline_Sale_Price_Y2-Pipeline_Purchase_Price_Y2)*(Increment+NPV_Rate_of_Inflation)^(G27-NPV_Increment)-Pipeline_Total_annual_cost_Y2*(Increment+NPV_Rate_of_Inflation)^(G27-NPV_Increment)-Pipeline_Carbon_Offsets__Paid_monthly_on_15th*(Increment+NPV_Rate_of_Inflation__Carbon_Offsets)^(G27-NPV_Increment)-D88 -> 92594688 | J27: 22 | K27: =Tanker_Quantity_demanded_Y2*(Increment+NPV_Gas_demand_rate)^(J27-NPV_Increment)*(NPV_LNG_Selling_price-NPV_LNG_Purchase_cost)*(Increment+NPV_Rate_of_Inflation)^(J27-NPV_Increment)-$B$56*(Increment+NPV_Rate_of_Inflation__Carbon_Offsets)^(J27-NPV_Increment)-$B$63*E26*(Increment+NPV_Rate_of_Inflation)^(J27-NPV_Increment)-Tanker_Total_Annual_Cost_Y2*(Increment+NPV_Rate_of_Inflation)^(J27-NPV_Increment)-D122 -> 1.108931e+08
A28: Inflatable Costs | D28: 24 | E28: 122 | G28: 23 | H28: =Pipeline_Sales_Y2*(Increment+Pipeline_Rate_of_increase_in_demand)^(G28-NPV_Increment)*(Pipeline_Sale_Price_Y2-Pipeline_Purchase_Price_Y2)*(Increment+NPV_Rate_of_Inflation)^(G28-NPV_Increment)-Pipeline_Total_annual_cost_Y2*(Increment+NPV_Rate_of_Inflation)^(G28-NPV_Increment)-Pipeline_Carbon_Offsets__Paid_monthly_on_15th*(Increment+NPV_Rate_of_Inflation__Carbon_Offsets)^(G28-NPV_Increment)-D89 -> 95172769 | J28: 23 | K28: =Tanker_Quantity_demanded_Y2*(Increment+NPV_Gas_demand_rate)^(J28-NPV_Increment)*(NPV_LNG_Selling_price-NPV_LNG_Purchase_cost)*(Increment+NPV_Rate_of_Inflation)^(J28-NPV_Increment)-$B$56*(Increment+NPV_Rate_of_Inflation__Carbon_Offsets)^(J28-NPV_Increment)-$B$63*E27*(Increment+NPV_Rate_of_Inflation)^(J28-NPV_Increment)-Tanker_Total_Annual_Cost_Y2*(Increment+NPV_Rate_of_Inflation)^(J28-NPV_Increment)-D123 -> 1.1235914e+08
A29: Pipeline Insurance, Y2 | B29: 2200000 | D29: 25 | E29: 123 | G29: 24 | H29: =Pipeline_Sales_Y2*(Increment+Pipeline_Rate_of_increase_in_demand)^(G29-NPV_Increment)*(Pipeline_Sale_Price_Y2-Pipeline_Purchase_Price_Y2)*(Increment+NPV_Rate_of_Inflation)^(G29-NPV_Increment)-Pipeline_Total_annual_cost_Y2*(Increment+NPV_Rate_of_Inflation)^(G29-NPV_Increment)-Pipeline_Carbon_Offsets__Paid_monthly_on_15th*(Increment+NPV_Rate_of_Inflation__Carbon_Offsets)^(G29-NPV_Increment)-D90 -> 97803377 | J29: 24 | K29: =Tanker_Quantity_demanded_Y2*(Increment+NPV_Gas_demand_rate)^(J29-NPV_Increment)*(NPV_LNG_Selling_price-NPV_LNG_Purchase_cost)*(Increment+NPV_Rate_of_Inflation)^(J29-NPV_Increment)-$B$56*(Increment+NPV_Rate_of_Inflation__Carbon_Offsets)^(J29-NPV_Increment)-$B$63*E28*(Increment+NPV_Rate_of_Inflation)^(J29-NPV_Increment)-Tanker_Total_Annual_Cost_Y2*(Increment+NPV_Rate_of_Inflation)^(J29-NPV_Increment)-D124 -> 1.1343312e+08
A30: Pipeline Operations Management, Y2 | B30: 1000000 | D30: 26 | E30: 123 | G30: 25 | H30: =Pipeline_Sales_Y2*(Increment+Pipeline_Rate_of_increase_in_demand)^(G30-NPV_Increment)*(Pipeline_Sale_Price_Y2-Pipeline_Purchase_Price_Y2)*(Increment+NPV_Rate_of_Inflation)^(G30-NPV_Increment)-Pipeline_Total_annual_cost_Y2*(Increment+NPV_Rate_of_Inflation)^(G30-NPV_Increment)-Pipeline_Carbon_Offsets__Paid_monthly_on_15th*(Increment+NPV_Rate_of_Inflation__Carbon_Offsets)^(G30-NPV_Increment)-D91 -> 1.0048755e+08 | J30: 25 | K30: =Tanker_Quantity_demanded_Y2*(Increment+NPV_Gas_demand_rate)^(J30-NPV_Increment)*(NPV_LNG_Selling_price-NPV_LNG_Purchase_cost)*(Increment+NPV_Rate_of_Inflation)^(J30-NPV_Increment)-$B$56*(Increment+NPV_Rate_of_Inflation__Carbon_Offsets)^(J30-NPV_Increment)-$B$63*E29*(Increment+NPV_Rate_of_Inflation)^(J30-NPV_Increment)-Tanker_Total_Annual_Cost_Y2*(Increment+NPV_Rate_of_Inflation)^(J30-NPV_Increment)-D125 -> 1.1447492e+08
A31: Pipeline Fuel Compression & Pumping, Y2 | B31: 4700000 | D31: 27 | E31: 124 | G31: 26 | H31: =Pipeline_Sales_Y2*(Increment+Pipeline_Rate_of_increase_in_demand)^(G31-NPV_Increment)*(Pipeline_Sale_Price_Y2-Pipeline_Purchase_Price_Y2)*(Increment+NPV_Rate_of_Inflation)^(G31-NPV_Increment)-Pipeline_Total_annual_cost_Y2*(Increment+NPV_Rate_of_Inflation)^(G31-NPV_Increment)-Pipeline_Carbon_Offsets__Paid_monthly_on_15th*(Increment+NPV_Rate_of_Inflation__Carbon_Offsets)^(G31-NPV_Increment)-D92 -> 1.0322633e+08 | J31: 26 | K31: =Tanker_Quantity_demanded_Y2*(Increment+NPV_Gas_demand_rate)^(J31-NPV_Increment)*(NPV_LNG_Selling_price-NPV_LNG_Purchase_cost)*(Increment+NPV_Rate_of_Inflation)^(J31-NPV_Increment)-$B$56*(Increment+NPV_Rate_of_Inflation__Carbon_Offsets)^(J31-NPV_Increment)-$B$63*E30*(Increment+NPV_Rate_of_Inflation)^(J31-NPV_Increment)-Tanker_Total_Annual_Cost_Y2*(Increment+NPV_Rate_of_Inflation)^(J31-NPV_Increment)-D126 -> 1.1586652e+08
A32: Pipeline General Maint. & Eng., Y2 | B32: 12000000 | D32: 28 | E32: 125 | G32: 27 | H32: =Pipeline_Sales_Y2*(Increment+Pipeline_Rate_of_increase_in_demand)^(G32-NPV_Increment)*(Pipeline_Sale_Price_Y2-Pipeline_Purchase_Price_Y2)*(Increment+NPV_Rate_of_Inflation)^(G32-NPV_Increment)-Pipeline_Total_annual_cost_Y2*(Increment+NPV_Rate_of_Inflation)^(G32-NPV_Increment)-Pipeline_Carbon_Offsets__Paid_monthly_on_15th*(Increment+NPV_Rate_of_Inflation__Carbon_Offsets)^(G32-NPV_Increment)-D93 -> 1.0602081e+08 | J32: 27 | K32: =Tanker_Quantity_demanded_Y2*(Increment+NPV_Gas_demand_rate)^(J32-NPV_Increment)*(NPV_LNG_Selling_price-NPV_LNG_Purchase_cost)*(Increment+NPV_Rate_of_Inflation)^(J32-NPV_Increment)-$B$56*(Increment+NPV_Rate_of_Inflation__Carbon_Offsets)^(J32-NPV_Increment)-$B$63*E31*(Increment+NPV_Rate_of_Inflation)^(J32-NPV_Increment)-Tanker_Total_Annual_Cost_Y2*(Increment+NPV_Rate_of_Inflation)^(J32-NPV_Increment)-D127 -> 1.168414e+08
A33: Pipeline Total Annual Cost, Y2 | B33: =SUM(B29:B32) -> 19900000 | D33: 29 | E33: 125 | G33: 28 | H33: =Pipeline_Sales_Y2*(Increment+Pipeline_Rate_of_increase_in_demand)^(G33-NPV_Increment)*(Pipeline_Sale_Price_Y2-Pipeline_Purchase_Price_Y2)*(Increment+NPV_Rate_of_Inflation)^(G33-NPV_Increment)-Pipeline_Total_annual_cost_Y2*(Increment+NPV_Rate_of_Inflation)^(G33-NPV_Increment)-Pipeline_Carbon_Offsets__Paid_monthly_on_15th*(Increment+NPV_Rate_of_Inflation__Carbon_Offsets)^(G33-NPV_Increment)-D94 -> 1.0887207e+08 | J33: 28 | K33: =Tanker_Quantity_demanded_Y2*(Increment+NPV_Gas_demand_rate)^(J33-NPV_Increment)*(NPV_LNG_Selling_price-NPV_LNG_Purchase_cost)*(Increment+NPV_Rate_of_Inflation)^(J33-NPV_Increment)-$B$56*(Increment+NPV_Rate_of_Inflation__Carbon_Offsets)^(J33-NPV_Increment)-$B$63*E32*(Increment+NPV_Rate_of_Inflation)^(J33-NPV_Increment)-Tanker_Total_Annual_Cost_Y2*(Increment+NPV_Rate_of_Inflation)^(J33-NPV_Increment)-D128 -> 1.1777559e+08
D34: 30 | E34: 126 | G34: 29 | H34: =Pipeline_Sales_Y2*(Increment+Pipeline_Rate_of_increase_in_demand)^(G34-NPV_Increment)*(Pipeline_Sale_Price_Y2-Pipeline_Purchase_Price_Y2)*(Increment+NPV_Rate_of_Inflation)^(G34-NPV_Increment)-Pipeline_Total_annual_cost_Y2*(Increment+NPV_Rate_of_Inflation)^(G34-NPV_Increment)-Pipeline_Carbon_Offsets__Paid_monthly_on_15th*(Increment+NPV_Rate_of_Inflation__Carbon_Offsets)^(G34-NPV_Increment)-D95 -> 1.1178124e+08 | J34: 29 | K34: =Tanker_Quantity_demanded_Y2*(Increment+NPV_Gas_demand_rate)^(J34-NPV_Increment)*(NPV_LNG_Selling_price-NPV_LNG_Purchase_cost)*(Increment+NPV_Rate_of_Inflation)^(J34-NPV_Increment)-$B$56*(Increment+NPV_Rate_of_Inflation__Carbon_Offsets)^(J34-NPV_Increment)-$B$63*E33*(Increment+NPV_Rate_of_Inflation)^(J34-NPV_Increment)-Tanker_Total_Annual_Cost_Y2*(Increment+NPV_Rate_of_Inflation)^(J34-NPV_Increment)-D129 -> 1.190682e+08
A35: Carbon Offset Cost | D35: 31 | E35: 126 | G35: 30 | H35: =Pipeline_Sales_Y2*(Increment+Pipeline_Rate_of_increase_in_demand)^(G35-NPV_Increment)*(Pipeline_Sale_Price_Y2-Pipeline_Purchase_Price_Y2)*(Increment+NPV_Rate_of_Inflation)^(G35-NPV_Increment)-Pipeline_Total_annual_cost_Y2*(Increment+NPV_Rate_of_Inflation)^(G35-NPV_Increment)-Pipeline_Carbon_Offsets__Paid_monthly_on_15th*(Increment+NPV_Rate_of_Inflation__Carbon_Offsets)^(G35-NPV_Increment)-D96 -> 1.1474943e+08 | J35: 30 | K35: =Tanker_Quantity_demanded_Y2*(Increment+NPV_Gas_demand_rate)^(J35-NPV_Increment)*(NPV_LNG_Selling_price-NPV_LNG_Purchase_cost)*(Increment+NPV_Rate_of_Inflation)^(J35-NPV_Increment)-$B$56*(Increment+NPV_Rate_of_Inflation__Carbon_Offsets)^(J35-NPV_Increment)-$B$63*E34*(Increment+NPV_Rate_of_Inflation)^(J35-NPV_Increment)-Tanker_Total_Annual_Cost_Y2*(Increment+NPV_Rate_of_Inflation)^(J35-NPV_Increment)-D130 -> 1.199174e+08
A36: Pipeline Carbon Offset, Y2 | B36: 800000 | G36: 31 | H36: =Pipeline_Sales_Y2*(Increment+Pipeline_Rate_of_increase_in_demand)^(G36-NPV_Increment)*(Pipeline_Sale_Price_Y2-Pipeline_Purchase_Price_Y2)*(Increment+NPV_Rate_of_Inflation)^(G36-NPV_Increment)-Pipeline_Total_annual_cost_Y2*(Increment+NPV_Rate_of_Inflation)^(G36-NPV_Increment)-Pipeline_Carbon_Offsets__Paid_monthly_on_15th*(Increment+NPV_Rate_of_Inflation__Carbon_Offsets)^(G36-NPV_Increment)-D97 -> 1.1777783e+08 | J36: 31 | K36: =Tanker_Quantity_demanded_Y2*(Increment+NPV_Gas_demand_rate)^(J36-NPV_Increment)*(NPV_LNG_Selling_price-NPV_LNG_Purchase_cost)*(Increment+NPV_Rate_of_Inflation)^(J36-NPV_Increment)-$B$56*(Increment+NPV_Rate_of_Inflation__Carbon_Offsets)^(J36-NPV_Increment)-$B$63*E35*(Increment+NPV_Rate_of_Inflation)^(J36-NPV_Increment)-Tanker_Total_Annual_Cost_Y2*(Increment+NPV_Rate_of_Inflation)^(J36-NPV_Increment)-D131 -> 1.211305e+08
G37: NPV | H37: =NPV(NPV__Rate_of_Financing,H7:H36)-Pipeline_Development_cost-PV(NPV_Rate_of_Inflation,NPV_Years_of_Operation+NPV_Development_Time__Yr,,Pipeline_Salvage_Value_Y31,0) -> 7.7784238e+08 | J37: NPV | K37: =NPV(NPV__Rate_of_Financing,K7:K36)-Tanker_Development_Cost+PV(NPV_Rate_of_Inflation,NPV_Years_of_Operation+NPV_Development_Time__Yr,,Tanker_Salvage_Value_Y31,0) -> 1.4562985e+09
A38: Tanker Inputs
A39: Tanker Development Cost | B39: 250000000 | J39: Key Assumptions made for this tanker NPV:
A40: Tanker Salvage Value, Y31 | B40: 20000000 | J40: $10M Cash Floor not considered in NPV calculations
A42: Revenues (LNG)
...

Sheet Sheet1

Sheet 2a), 4) Inputs
A1: QatarEnergy
A2: Inputs
A4: Time and Date | D4: Year 1 Expenses | G4: Round Trips Required | J4: Months | K4: Days | M4: Color Key
A5: First Year | B5: 1 | D5: Liquid Natural Gas, Y1 | G5: Period | H5: # of Trips | J5: Jan | K5: 31 | M5: Black = Scaffolding, calculated values (do not overwrite)
A6: Days in Year | B6: =SUM(K5:K16) -> 365.25 | D6: Annual Demand, Y1 | E6: 0 | G6: 1 | J6: Feb | K6: 28.25 | M6: Pink = calculated value from other sheet (do not overwrite)
A7: Weeks in Year | B7: 52 | G7: 2 | H7: =ROUNDUP(Quantity_demand_Y2*(Increment+Gas_demand_rate)^(G7-$B$11)/Capacity_per_trip,0) -> 109 | J7: Mar | K7: 31 | M7: Red = external data (editable)
A8: Months in Year | B8: 12 | D8: Inflatable Costs, Y1 | G8: 3 | H8: =ROUNDUP(Quantity_demand_Y2*(Increment+Gas_demand_rate)^(G8-$B$11)/Capacity_per_trip,0) -> 110 | J8: Apr | K8: 30 | M8: Black on Blue = Owner's decision
A9: Increment | B9: 1 | D9: Insurance Expense, Y1 | E9: 0 | G9: 4 | H9: =ROUNDUP(Quantity_demand_Y2*(Increment+Gas_demand_rate)^(G9-$B$11)/Capacity_per_trip,0) -> 111 | J9: May | K9: 31 | N9: Gray shade (stay out!)
A10: Deferred Year | B10: =11/12 -> 0.91666667 | D10: Port Fees per Round Trip, Y1 | E10: 0 | G10: 5 | H10: =ROUNDUP(Quantity_demand_Y2*(Increment+Gas_demand_rate)^(G10-$B$11)/Capacity_per_trip,0) -> 111 | J10: Jun | K10: 30
A11: Inflation Increment | B11: 2 | D11: Operating Expense per Round Trip, Y1 | E11: 0 | G11: 6 | H11: =ROUNDUP(Quantity_demand_Y2*(Increment+Gas_demand_rate)^(G11-$B$11)/Capacity_per_trip,0) -> 112 | J11: Jul | K11: 31
A12: Half Year Increment | B12: 6 | D12: Annual General Maintenance Expense, Y1 | E12: 0 | G12: 7 | H12: =ROUNDUP(Quantity_demand_Y2*(Increment+Gas_demand_rate)^(G12-$B$11)/Capacity_per_trip,0) -> 112 | J12: Aug | K12: 31
D13: Annual Stores & Lubricants Expense, Y1 | E13: 0 | G13: 8 | H13: =ROUNDUP(Quantity_demand_Y2*(Increment+Gas_demand_rate)^(G13-$B$11)/Capacity_per_trip,0) -> 113 | J13: Sep | K13: 30 | M13: Named Ranges | N13: =_xlfn.CONCAT("Count: ",COUNTA(N14:N79)) -> Count: 66
A14: Tanker Costs | G14: 9 | H14: =ROUNDUP(Quantity_demand_Y2*(Increment+Gas_demand_rate)^(G14-$B$11)/Capacity_per_trip,0) -> 113 | J14: Oct | K14: 31 | M14: Annual_depreciation | N14: ='2a), 4) Inputs'!$E$20
A15: Capacity per Round Trip | B15: 260000 | D15: Crew Costs, Y1 | G15: 10 | H15: =ROUNDUP(Quantity_demand_Y2*(Increment+Gas_demand_rate)^(G15-$B$11)/Capacity_per_trip,0) -> 114 | J15: Nov | K15: 30 | M15: Annual_salary_base_costs | N15: ='2a), 4) Inputs'!$E$37
A16: Useful Life | B16: 30 | D16: Payment to Employees, Y1 | E16: 0 | G16: 11 | H16: =ROUNDUP(Quantity_demand_Y2*(Increment+Gas_demand_rate)^(G16-$B$11)/Capacity_per_trip,0) -> 114 | J16: Dec | K16: 31 | M16: Annual_salary_costs | N16: ='2a), 4) Inputs'!$E$36
A17: Salvage Value | B17: 20000000 | D17: Employee Social Insurance Contribution, Y1 | E17: 0 | G17: 12 | H17: =ROUNDUP(Quantity_demand_Y2*(Increment+Gas_demand_rate)^(G17-$B$11)/Capacity_per_trip,0) -> 115 | M17: Bank_rate | N17: ='2a), 4) Inputs'!$B$24
A18: Development Cost | B18: 250000000 | D18: Employer Social Insurance Contribution, Y1 | E18: 0 | G18: 13 | H18: =ROUNDUP(Quantity_demand_Y2*(Increment+Gas_demand_rate)^(G18-$B$11)/Capacity_per_trip,0) -> 116 | M18: Capacity_per_trip | N18: ='2a), 4) Inputs'!$B$15
A19: Minimum Cash Balance | B19: 10000000 | G19: 14 | H19: =ROUNDUP(Quantity_demand_Y2*(Increment+Gas_demand_rate)^(G19-$B$11)/Capacity_per_trip,0) -> 116 | M19: Carbon_offset | N19: ='2a), 4) Inputs'!$B$37
A20: Opening Cash | B20: 0 | D20: Depreciation Expense, Y1 | E20: 0 | G20: 15 | H20: =ROUNDUP(Quantity_demand_Y2*(Increment+Gas_demand_rate)^(G20-$B$11)/Capacity_per_trip,0) -> 117 | M20: Carbon_offset_rate | N20: ='2a), 4) Inputs'!$B$26
G21: 16 | H21: =ROUNDUP(Quantity_demand_Y2*(Increment+Gas_demand_rate)^(G21-$B$11)/Capacity_per_trip,0) -> 117 | M21: Corporate_tax_rate | N21: ='2a), 4) Inputs'!$B$27
A22: Rates | D22: Year 2 Expenses | G22: 17 | H22: =ROUNDUP(Quantity_demand_Y2*(Increment+Gas_demand_rate)^(G22-$B$11)/Capacity_per_trip,0) -> 118 | M22: Daily_demand_LNG_Y2 | N22: ='2b) Schedules'!$R$25
A23: Inflation Rate | B23: 0.015 | D23: Liquid Natural Gas, Y2 | G23: 18 | H23: =ROUNDUP(Quantity_demand_Y2*(Increment+Gas_demand_rate)^(G23-$B$11)/Capacity_per_trip,0) -> 119 | M23: Days_in_year | N23: ='2a), 4) Inputs'!$B$6
A24: Bank Rate | B24: 0.04 | D24: Annual Demand, Y2 | E24: 28330000 | G24: 19 | H24: =ROUNDUP(Quantity_demand_Y2*(Increment+Gas_demand_rate)^(G24-$B$11)/Capacity_per_trip,0) -> 119 | M24: Deferred_year | N24: ='2a), 4) Inputs'!$B$10
A25: Gas Demand Rate | B25: 0.005 | D25: Purchase Cost, Y2 | E25: 22 | G25: 20 | H25: =ROUNDUP(Quantity_demand_Y2*(Increment+Gas_demand_rate)^(G25-$B$11)/Capacity_per_trip,0) -> 120 | M25: Depreciation_expense_Y1 | N25: ='2a), 4) Inputs'!$E$20
A26: Carbon Offset Rate | B26: 0.039 | D26: Selling Price, Y2 | E26: 28 | G26: 21 | H26: =ROUNDUP(Quantity_demand_Y2*(Increment+Gas_demand_rate)^(G26-$B$11)/Capacity_per_trip,0) -> 120 | M26: Development_cost | N26: ='2a), 4) Inputs'!$B$18
A27: Corporate Tax Rate | B27: 0 | G27: 22 | H27: =ROUNDUP(Quantity_demand_Y2*(Increment+Gas_demand_rate)^(G27-$B$11)/Capacity_per_trip,0) -> 121 | M27: Employee_contribution | N27: ='2a), 4) Inputs'!$E$39
A28: Employee Social Insurance Rate | B28: 0.07 | D28: Inflatable Costs Y2 | G28: 23 | H28: =ROUNDUP(Quantity_demand_Y2*(Increment+Gas_demand_rate)^(G28-$B$11)/Capacity_per_trip,0) -> 121 | M28: Employer_contribution | N28: ='2a), 4) Inputs'!$E$40
A29: Employer Social Insurance Rate | B29: 0.14 | D29: Insurance Expense, Y2 | E29: 1800000 | G29: 24 | H29: =ROUNDUP(Quantity_demand_Y2*(Increment+Gas_demand_rate)^(G29-$B$11)/Capacity_per_trip,0) -> 122 | M29: First_year | N29: ='2a), 4) Inputs'!$B$5
D30: Port Fees per Round Trip, Y2 | E30: 220000 | G30: 25 | H30: =ROUNDUP(Quantity_demand_Y2*(Increment+Gas_demand_rate)^(G30-$B$11)/Capacity_per_trip,0) -> 123 | M30: Gas_demand_rate | N30: ='2a), 4) Inputs'!$B$25
A31: Heavy Fuel Oil Per Round Trip | D31: Operating Expense per Round Trip, Y2 | E31: 40000 | G31: 26 | H31: =ROUNDUP(Quantity_demand_Y2*(Increment+Gas_demand_rate)^(G31-$B$11)/Capacity_per_trip,0) -> 123 | M31: General_maintenance | N31: ='2a), 4) Inputs'!$E$32
A32: Price per Ton of HFO, Y1 | B32: 380 | D32: Annual General Maintenance Expense, Y2 | E32: 2000000 | G32: 27 | H32: =ROUNDUP(Quantity_demand_Y2*(Increment+Gas_demand_rate)^(G32-$B$11)/Capacity_per_trip,0) -> 124 | M32: Heavy_fuel_oil | N32: ='2b) Schedules'!$R$26
A33: Tons per Round Trip | B33: 24 | D33: Annual Stores & Lubricants Expense, Y2 | E33: 2000000 | G33: 28 | H33: =ROUNDUP(Quantity_demand_Y2*(Increment+Gas_demand_rate)^(G33-$B$11)/Capacity_per_trip,0) -> 125 | M33: Increment | N33: ='2a), 4) Inputs'!$B$9
G34: 29 | H34: =ROUNDUP(Quantity_demand_Y2*(Increment+Gas_demand_rate)^(G34-$B$11)/Capacity_per_trip,0) -> 125 | M34: Inflation_rate | N34: ='2a), 4) Inputs'!$B$23
A35: Carbon Offset Costs | D35: Crew Costs, Y2 | G35: 30 | H35: =ROUNDUP(Quantity_demand_Y2*(Increment+Gas_demand_rate)^(G35-$B$11)/Capacity_per_trip,0) -> 126 | M35: Insurance_expense | N35: ='2a), 4) Inputs'!$E$29
A36: Carbon Offset, Y1 | D36: Annual Total Salary Expense, Y2 | E36: 3500000 | G36: 31 | H36: =ROUNDUP(Quantity_demand_Y2*(Increment+Gas_demand_rate)^(G36-$B$11)/Capacity_per_trip,0) -> 126 | M36: Minimum_balance | N36: ='2a), 4) Inputs'!$B$19
A37: Carbon Offset, Y2 | B37: 33000000 | D37: Annual Base Salary Expense, Y2 | E37: =Annual_salary_costs/(1+B29) -> 3070175.4 | M37: Months_in_year | N37: ='2a), 4) Inputs'!$B$8
D38: Payment to Employees, Y2 | E38: =Annual_salary_base_costs-Employee_contribution -> 2855263.2 | M38: NPV__Rate_of_Financing | N38: ='1) NPV Comparison'!$B$15
A39: What-If? Costs | D39: Employee Social Insurance Contribution, Y2 | E39: =Annual_salary_base_costs*B28 -> 214912.28 | M39: NPV_Development_Time__Yr | N39: ='1) NPV Comparison'!$B$7
A40: Port Damage, Y3 | B40: 5000000 | D40: Employer Social Insurance Contribution, Y2 | E40: =B29*E37 -> 429824.56 | M40: NPV_First_Year | N40: ='1) NPV Comparison'!$K$37
A41: Insurance Coverage - Damage, Y3 | B41: 0.9 | M41: NPV_Gas_demand_rate | N41: ='1) NPV Comparison'!$B$16
...

Sheet 2b) Schedules
A1: QatarEnergy
A2: Schedules
A4: Bank Loan | H4: Operating Expenses (Annual) | Q4: Gross Profit
A5: Period | B5: Principal | C5: Interest | D5: Payment | E5: Reduction | F5: Remaining | H5: Year | I5: Insurance | J5: Ann Base Sal. | K5: Emp'r Social Ins. | L5: Maintenance | M5: Stores & Lubricant | N5: Carbon Offset | O5: Total Annual Cost | Q5: Year | R5: Sales | S5: COGS | T5: Gross profit
A6: =First_year -> 1 | B6: =Development_cost+'2a), 4) Inputs'!B19 -> 260000000 | C6: =B6*(Bank_rate)*('2a), 4) Inputs'!B12/'2a), 4) Inputs'!B8) -> 5200000 | E6: =C6-D6 -> 5200000 | F6: =C6+B6 -> 265200000 | H6: =First_year -> 1 | Q6: =First_year -> 1
A7: =A6+Increment -> 2 | B7: =F6 -> 265200000 | C7: =B7*(Bank_rate) -> 10608000 | D7: =PMT(Bank_rate,COUNTA(A7:A36),B7,0)*-1 -> 15336542 | E7: =C7-D7 -> -4728542.3 | F7: =E7+B7 -> 2.6047146e+08 | H7: =H6+Increment -> 2 | I7: =Insurance_expense -> 1800000 | J7: =Annual_salary_base_costs -> 3070175.4 | K7: =Employer_contribution -> 429824.56 | L7: =General_maintenance -> 2000000 | M7: =Stores_and_lubricants -> 2000000 | N7: =Carbon_offset -> 33000000 | O7: =SUM(I7:N7) -> 42300000 | Q7: =Q6+Increment -> 2 | R7: =Quantity_demand_Y2*(Increment+Gas_demand_rate)^(Q7-'2a), 4) Inputs'!$B$11)*Selling_price_LNG_Y2*(Increment+Inflation_rate)^(Q7-'2a), 4) Inputs'!$B$11) -> 793240000 | S7: =Quantity_demand_Y2*(Increment+Gas_demand_rate)^(Q7-'2a), 4) Inputs'!$B$11)*Purchase_cost_LNG*(Increment+Inflation_rate)^(Q7-'2a), 4) Inputs'!$B$11) -> 623260000 | T7: =R7-S7 -> 169980000
A8: =A7+Increment -> 3 | B8: =F7 -> 2.6047146e+08 | C8: =B8*(Bank_rate) -> 10418858 | D8: =D7 -> 15336542 | E8: =C8-D8 -> -4917684 | F8: =E8+B8 -> 2.5555377e+08 | H8: =H7+Increment -> 3 | I8: =I7*(Inflation_rate+Increment) -> 1827000 | J8: =J7*(Inflation_rate+Increment) -> 3116228.1 | K8: =K7*(Inflation_rate+Increment) -> 436271.93 | L8: =L7*(Inflation_rate+Increment) -> 2030000 | M8: =M7*(Inflation_rate+Increment) -> 2030000 | N8: =N7*(Carbon_offset_rate+Increment) -> 34287000 | O8: =SUM(I8:N8) -> 43726500 | Q8: =Q7+Increment -> 3 | R8: =Quantity_demand_Y2*(Increment+Gas_demand_rate)^(Q8-'2a), 4) Inputs'!$B$11)*Selling_price_LNG_Y2*(Increment+Inflation_rate)^(Q8-'2a), 4) Inputs'!$B$11) -> 8.0916429e+08 | S8: =Quantity_demand_Y2*(Increment+Gas_demand_rate)^(Q8-'2a), 4) Inputs'!$B$11)*Purchase_cost_LNG*(Increment+Inflation_rate)^(Q8-'2a), 4) Inputs'!$B$11) -> 6.3577194e+08 | T8: =R8-S8 -> 1.7339235e+08
A9: =A8+Increment -> 4 | B9: =F8 -> 2.5555377e+08 | C9: =B9*(Bank_rate) -> 10222151 | D9: =D8 -> 15336542 | E9: =C9-D9 -> -5114391.3 | F9: =E9+B9 -> 2.5043938e+08 | H9: =H8+Increment -> 4 | I9: =I8*(Inflation_rate+Increment) -> 1854405 | J9: =J8*(Inflation_rate+Increment) -> 3162971.5 | K9: =K8*(Inflation_rate+Increment) -> 442816.01 | L9: =L8*(Inflation_rate+Increment) -> 2060450 | M9: =M8*(Inflation_rate+Increment) -> 2060450 | N9: =N8*(Carbon_offset_rate+Increment) -> 35624193 | O9: =SUM(I9:N9) -> 45205286 | Q9: =Q8+Increment -> 4 | R9: =Quantity_demand_Y2*(Increment+Gas_demand_rate)^(Q9-'2a), 4) Inputs'!$B$11)*Selling_price_LNG_Y2*(Increment+Inflation_rate)^(Q9-'2a), 4) Inputs'!$B$11) -> 8.2540827e+08 | S9: =Quantity_demand_Y2*(Increment+Gas_demand_rate)^(Q9-'2a), 4) Inputs'!$B$11)*Purchase_cost_LNG*(Increment+Inflation_rate)^(Q9-'2a), 4) Inputs'!$B$11) -> 6.4853507e+08 | T9: =R9-S9 -> 1.768732e+08
A10: =A9+Increment -> 5 | B10: =F9 -> 2.5043938e+08 | C10: =B10*(Bank_rate) -> 10017575 | D10: =D9 -> 15336542 | E10: =C10-D10 -> -5318967 | F10: =E10+B10 -> 2.4512042e+08 | H10: =H9+Increment -> 5 | I10: =I9*(Inflation_rate+Increment) -> 1882221.1 | J10: =J9*(Inflation_rate+Increment) -> 3210416.1 | K10: =K9*(Inflation_rate+Increment) -> 449458.25 | L10: =L9*(Inflation_rate+Increment) -> 2091356.7 | M10: =M9*(Inflation_rate+Increment) -> 2091356.7 | N10: =N9*(Y5_CO_Rate+Increment) -> 71248386 | O10: =SUM(I10:N10) -> 80973195 | Q10: =Q9+Increment -> 5 | R10: =Quantity_demand_Y2*(Increment+Gas_demand_rate)^(Q10-'2a), 4) Inputs'!$B$11)*Selling_price_LNG_Y2*(Increment+Inflation_rate)^(Q10-'2a), 4) Inputs'!$B$11) -> 8.4197834e+08 | S10: =Quantity_demand_Y2*(Increment+Gas_demand_rate)^(Q10-'2a), 4) Inputs'!$B$11)*Purchase_cost_LNG*(Increment+Inflation_rate)^(Q10-'2a), 4) Inputs'!$B$11) -> 6.6155441e+08 | T10: =R10-S10 -> 1.8042393e+08
A11: =A10+Increment -> 6 | B11: =F10 -> 2.4512042e+08 | C11: =B11*(Bank_rate) -> 9804816.6 | D11: =D10 -> 15336542 | E11: =C11-D11 -> -5531725.7 | F11: =E11+B11 -> 2.3958869e+08
A12: =A11+Increment -> 7 | B12: =F11 -> 2.3958869e+08 | C12: =B12*(Bank_rate) -> 9583547.6 | D12: =D11 -> 15336542 | E12: =C12-D12 -> -5752994.7 | F12: =E12+B12 -> 2.338357e+08 | Q12: LNG Price
A13: =A12+Increment -> 8 | B13: =F12 -> 2.338357e+08 | C13: =B13*(Bank_rate) -> 9353427.8 | D13: =D12 -> 15336542 | E13: =C13-D13 -> -5983114.5 | F13: =E13+B13 -> 2.2785258e+08 | H13: Round Trip Expenses (Annual) | Q13: Year | R13: 3 | S13: 4 | T13: 5
A14: =A13+Increment -> 9 | B14: =F13 -> 2.2785258e+08 | C14: =B14*(Bank_rate) -> 9114103.2 | D14: =D13 -> 15336542 | E14: =C14-D14 -> -6222439.1 | F14: =E14+B14 -> 2.2163014e+08 | H14: Year | I14: Tons of HFO per Year | J14: Heavy Fuel Oil | K14: Port Fee | L14: OpEx | M14: Total Annual Cost | Q14: Selling Price of LNG | R14: =Selling_price_LNG_Y2*(Increment+Inflation_rate) -> 28.42 | S14: =Selling_price_LNG_Y2*(Increment+Inflation_rate)*(Increment+Inflation_rate) -> 28.8463 | T14: =Selling_price_LNG_Y2*(Increment+Inflation_rate)*(Increment+Inflation_rate)*(Increment+Inflation_rate) -> 29.278994
A15: =A14+Increment -> 10 | B15: =F14 -> 2.2163014e+08 | C15: =B15*(Bank_rate) -> 8865205.7 | D15: =D14 -> 15336542 | E15: =C15-D15 -> -6471336.6 | F15: =E15+B15 -> 2.151588e+08 | H15: =First_year -> 1 | Q15: Purchase Price of LNG | R15: =Purchase_cost_LNG*(Increment+Inflation_rate) -> 22.33 | S15: =Purchase_cost_LNG*(Increment+Inflation_rate)*(Increment+Inflation_rate) -> 22.66495 | T15: =Purchase_cost_LNG*(Increment+Inflation_rate)*(Increment+Inflation_rate)*(Increment+Inflation_rate) -> 23.004924
A16: =A15+Increment -> 11 | B16: =F15 -> 2.151588e+08 | C16: =B16*(Bank_rate) -> 8606352.2 | D16: =D15 -> 15336542 | E16: =C16-D16 -> -6730190.1 | F16: =E16+B16 -> 2.0842861e+08 | H16: =H15+Increment -> 2 | I16: =Tons_per_trip*'2a), 4) Inputs'!H7 -> 2616 | J16: =Price_per_ton*(Increment+Inflation_rate)^(H16-'2a), 4) Inputs'!$B$11)*I16 -> 994080 | K16: =Port_fee*(Increment+Inflation_rate)^(H16-'2a), 4) Inputs'!$B$11)*'2a), 4) Inputs'!H7 -> 23980000 | L16: =Operating_expense*(Increment+Inflation_rate)^(H16-'2a), 4) Inputs'!$B$11)*'2a), 4) Inputs'!H7 -> 4360000 | M16: =J16+K16+L16 -> 29334080
A17: =A16+Increment -> 12 | B17: =F16 -> 2.0842861e+08 | C17: =B17*(Bank_rate) -> 8337144.6 | D17: =D16 -> 15336542 | E17: =C17-D17 -> -6999397.7 | F17: =E17+B17 -> 2.0142922e+08 | H17: =H16+Increment -> 3 | I17: =Tons_per_trip*'2a), 4) Inputs'!H8 -> 2640 | J17: =Price_per_ton*(Increment+Inflation_rate)^(H17-'2a), 4) Inputs'!$B$11)*I17 -> 1018248 | K17: =Port_fee*(Increment+Inflation_rate)^(H17-'2a), 4) Inputs'!$B$11)*'2a), 4) Inputs'!H8 -> 24563000 | L17: =Operating_expense*(Increment+Inflation_rate)^(H17-'2a), 4) Inputs'!$B$11)*'2a), 4) Inputs'!H8 -> 4466000 | M17: =J17+K17+L17 -> 30047248 | Q17: Annual Depreciation
A18: =A17+Increment -> 13 | B18: =F17 -> 2.0142922e+08 | C18: =B18*(Bank_rate) -> 8057168.7 | D18: =D17 -> 15336542 | E18: =C18-D18 -> -7279373.6 | F18: =E18+B18 -> 1.9414984e+08 | H18: =H17+Increment -> 4 | I18: =Tons_per_trip*'2a), 4) Inputs'!H9 -> 2664 | J18: =Price_per_ton*(Increment+Inflation_rate)^(H18-'2a), 4) Inputs'!$B$11)*I18 -> 1042917.4 | K18: =Port_fee*(Increment+Inflation_rate)^(H18-'2a), 4) Inputs'!$B$11)*'2a), 4) Inputs'!H9 -> 25158094 | L18: =Operating_expense*(Increment+Inflation_rate)^(H18-'2a), 4) Inputs'!$B$11)*'2a), 4) Inputs'!H9 -> 4574199 | M18: =J18+K18+L18 -> 30775211 | Q18: Year | R18: Depreciation
A19: =A18+Increment -> 14 | B19: =F18 -> 1.9414984e+08 | C19: =B19*(Bank_rate) -> 7765993.7 | D19: =D18 -> 15336542 | E19: =C19-D19 -> -7570548.6 | F19: =E19+B19 -> 1.8657929e+08 | H19: =H18+Increment -> 5 | I19: =Tons_per_trip*'2a), 4) Inputs'!H10 -> 2664 | J19: =Price_per_ton*(Increment+Inflation_rate)^(H19-'2a), 4) Inputs'!$B$11)*I19 -> 1058561.1 | K19: =Port_fee*(Increment+Inflation_rate)^(H19-'2a), 4) Inputs'!$B$11)*'2a), 4) Inputs'!H10 -> 25535466 | L19: =Operating_expense*(Increment+Inflation_rate)^(H19-'2a), 4) Inputs'!$B$11)*'2a), 4) Inputs'!H10 -> 4642812 | M19: =J19+K19+L19 -> 31236839 | Q19: =First_year -> 1 | R19: =Depreciation_expense_Y1 -> 0
A20: =A19+Increment -> 15 | B20: =F19 -> 1.8657929e+08 | C20: =B20*(Bank_rate) -> 7463171.8 | D20: =D19 -> 15336542 | E20: =C20-D20 -> -7873370.5 | F20: =E20+B20 -> 1.7870592e+08 | Q20: =Q19+Increment -> 2 | R20: =(Development_cost-Salvage_value)/Useful_life -> 7666666.7
A21: =A20+Increment -> 16 | B21: =F20 -> 1.7870592e+08 | C21: =B21*(Bank_rate) -> 7148237 | D21: =D20 -> 15336542 | E21: =C21-D21 -> -8188305.3 | F21: =E21+B21 -> 1.7051762e+08 | Q21: =Q20+Increment -> 3 | R21: =(Development_cost-Salvage_value)/Useful_life -> 7666666.7
A22: =A21+Increment -> 17 | B22: =F21 -> 1.7051762e+08 | C22: =B22*(Bank_rate) -> 6820704.8 | D22: =D21 -> 15336542 | E22: =C22-D22 -> -8515837.5 | F22: =E22+B22 -> 1.6200178e+08 | H22: Year 2 Gross Profit | Q22: =Q21+Increment -> 4 | R22: =(Development_cost-Salvage_value)/Useful_life -> 7666666.7
A23: =A22+Increment -> 18 | B23: =F22 -> 1.6200178e+08 | C23: =B23*(Bank_rate) -> 6480071.3 | D23: =D22 -> 15336542 | E23: =C23-D23 -> -8856471 | F23: =E23+B23 -> 1.5314531e+08 | H23: Period | I23: Qty Demanded | J23: Sales | K23: COGS | L23: Gross profit | Q23: =Q22+Increment -> 5 | R23: =(Development_cost-Salvage_value)/Useful_life -> 7666666.7
A24: =A23+Increment -> 19 | B24: =F23 -> 1.5314531e+08 | C24: =B24*(Bank_rate) -> 6125812.4 | D24: =D23 -> 15336542 | E24: =C24-D24 -> -9210729.9 | F24: =E24+B24 -> 1.4393458e+08 | H24: Jan | I24: =Daily_demand_LNG_Y2*_xlfn.XLOOKUP(H24,'2a), 4) Inputs'!$J$5:$J$16,'2a), 4) Inputs'!$K$5:$K$16) -> 2404462.7 | J24: =I24*Selling_price_LNG_Y2 -> 67324956 | K24: =I24*Purchase_cost_LNG -> 52898179 | L24: =J24-K24 -> 14426776
A25: =A24+Increment -> 20 | B25: =F24 -> 1.4393458e+08 | C25: =B25*(Bank_rate) -> 5757383.2 | D25: =D24 -> 15336542 | E25: =C25-D25 -> -9579159.1 | F25: =E25+B25 -> 1.3435542e+08 | H25: Feb | I25: =Daily_demand_LNG_Y2*_xlfn.XLOOKUP(H25,'2a), 4) Inputs'!$J$5:$J$16,'2a), 4) Inputs'!$K$5:$K$16) -> 2191163.6 | J25: =I25*Selling_price_LNG_Y2 -> 61352580 | K25: =I25*Purchase_cost_LNG -> 48205599 | L25: =J25-K25 -> 13146982 | Q25: Daily Demand Y2 | R25: =Quantity_demand_Y2/Days_in_year -> 77563.313
A26: =A25+Increment -> 21 | B26: =F25 -> 1.3435542e+08 | C26: =B26*(Bank_rate) -> 5374216.9 | D26: =D25 -> 15336542 | E26: =C26-D26 -> -9962325.4 | F26: =E26+B26 -> 1.243931e+08 | H26: Mar | I26: =Daily_demand_LNG_Y2*_xlfn.XLOOKUP(H26,'2a), 4) Inputs'!$J$5:$J$16,'2a), 4) Inputs'!$K$5:$K$16) -> 2404462.7 | J26: =I26*Selling_price_LNG_Y2 -> 67324956 | K26: =I26*Purchase_cost_LNG -> 52898179 | L26: =J26-K26 -> 14426776 | Q26: HFO per round trip | R26: =Price_per_ton*Tons_per_trip -> 9120
A27: =A26+Increment -> 22 | B27: =F26 -> 1.243931e+08 | C27: =B27*(Bank_rate) -> 4975723.8 | D27: =D26 -> 15336542 | E27: =C27-D27 -> -10360818 | F27: =E27+B27 -> 1.1403228e+08 | H27: Apr | I27: =Daily_demand_LNG_Y2*_xlfn.XLOOKUP(H27,'2a), 4) Inputs'!$J$5:$J$16,'2a), 4) Inputs'!$K$5:$K$16) -> 2326899.4 | J27: =I27*Selling_price_LNG_Y2 -> 65153183 | K27: =I27*Purchase_cost_LNG -> 51191786 | L27: =J27-K27 -> 13961396
A28: =A27+Increment -> 23 | B28: =F27 -> 1.1403228e+08 | C28: =B28*(Bank_rate) -> 4561291.1 | D28: =D27 -> 15336542 | E28: =C28-D28 -> -10775251 | F28: =E28+B28 -> 1.0325703e+08 | H28: May | I28: =Daily_demand_LNG_Y2*_xlfn.XLOOKUP(H28,'2a), 4) Inputs'!$J$5:$J$16,'2a), 4) Inputs'!$K$5:$K$16) -> 2404462.7 | J28: =I28*Selling_price_LNG_Y2 -> 67324956 | K28: =I28*Purchase_cost_LNG -> 52898179 | L28: =J28-K28 -> 14426776
A29: =A28+Increment -> 24 | B29: =F28 -> 1.0325703e+08 | C29: =B29*(Bank_rate) -> 4130281.1 | D29: =D28 -> 15336542 | E29: =C29-D29 -> -11206261 | F29: =E29+B29 -> 92050765 | H29: Jun | I29: =Daily_demand_LNG_Y2*_xlfn.XLOOKUP(H29,'2a), 4) Inputs'!$J$5:$J$16,'2a), 4) Inputs'!$K$5:$K$16) -> 2326899.4 | J29: =I29*Selling_price_LNG_Y2 -> 65153183 | K29: =I29*Purchase_cost_LNG -> 51191786 | L29: =J29-K29 -> 13961396
A30: =A29+Increment -> 25 | B30: =F29 -> 92050765 | C30: =B30*(Bank_rate) -> 3682030.6 | D30: =D29 -> 15336542 | E30: =C30-D30 -> -11654512 | F30: =E30+B30 -> 80396254 | H30: Jul | I30: =Daily_demand_LNG_Y2*_xlfn.XLOOKUP(H30,'2a), 4) Inputs'!$J$5:$J$16,'2a), 4) Inputs'!$K$5:$K$16) -> 2404462.7 | J30: =I30*Selling_price_LNG_Y2 -> 67324956 | K30: =I30*Purchase_cost_LNG -> 52898179 | L30: =J30-K30 -> 14426776
A31: =A30+Increment -> 26 | B31: =F30 -> 80396254 | C31: =B31*(Bank_rate) -> 3215850.1 | D31: =D30 -> 15336542 | E31: =C31-D31 -> -12120692 | F31: =E31+B31 -> 68275561 | H31: Aug | I31: =Daily_demand_LNG_Y2*_xlfn.XLOOKUP(H31,'2a), 4) Inputs'!$J$5:$J$16,'2a), 4) Inputs'!$K$5:$K$16) -> 2404462.7 | J31: =I31*Selling_price_LNG_Y2 -> 67324956 | K31: =I31*Purchase_cost_LNG -> 52898179 | L31: =J31-K31 -> 14426776
A32: =A31+Increment -> 27 | B32: =F31 -> 68275561 | C32: =B32*(Bank_rate) -> 2731022.5 | D32: =D31 -> 15336542 | E32: =C32-D32 -> -12605520 | F32: =E32+B32 -> 55670042 | H32: Sep | I32: =Daily_demand_LNG_Y2*_xlfn.XLOOKUP(H32,'2a), 4) Inputs'!$J$5:$J$16,'2a), 4) Inputs'!$K$5:$K$16) -> 2326899.4 | J32: =I32*Selling_price_LNG_Y2 -> 65153183 | K32: =I32*Purchase_cost_LNG -> 51191786 | L32: =J32-K32 -> 13961396
A33: =A32+Increment -> 28 | B33: =F32 -> 55670042 | C33: =B33*(Bank_rate) -> 2226801.7 | D33: =D32 -> 15336542 | E33: =C33-D33 -> -13109741 | F33: =E33+B33 -> 42560301 | H33: Oct | I33: =Daily_demand_LNG_Y2*_xlfn.XLOOKUP(H33,'2a), 4) Inputs'!$J$5:$J$16,'2a), 4) Inputs'!$K$5:$K$16) -> 2404462.7 | J33: =I33*Selling_price_LNG_Y2 -> 67324956 | K33: =I33*Purchase_cost_LNG -> 52898179 | L33: =J33-K33 -> 14426776
A34: =A33+Increment -> 29 | B34: =F33 -> 42560301 | C34: =B34*(Bank_rate) -> 1702412 | D34: =D33 -> 15336542 | E34: =C34-D34 -> -13634130 | F34: =E34+B34 -> 28926171 | H34: Nov | I34: =Daily_demand_LNG_Y2*_xlfn.XLOOKUP(H34,'2a), 4) Inputs'!$J$5:$J$16,'2a), 4) Inputs'!$K$5:$K$16) -> 2326899.4 | J34: =I34*Selling_price_LNG_Y2 -> 65153183 | K34: =I34*Purchase_cost_LNG -> 51191786 | L34: =J34-K34 -> 13961396
A35: =A34+Increment -> 30 | B35: =F34 -> 28926171 | C35: =B35*(Bank_rate) -> 1157046.8 | D35: =D34 -> 15336542 | E35: =C35-D35 -> -14179495 | F35: =E35+B35 -> 14746675 | H35: Dec | I35: =Daily_demand_LNG_Y2*_xlfn.XLOOKUP(H35,'2a), 4) Inputs'!$J$5:$J$16,'2a), 4) Inputs'!$K$5:$K$16) -> 2404462.7 | J35: =I35*Selling_price_LNG_Y2 -> 67324956 | K35: =I35*Purchase_cost_LNG -> 52898179 | L35: =J35-K35 -> 14426776
A36: =A35+Increment -> 31 | B36: =F35 -> 14746675 | C36: =B36*(Bank_rate) -> 589867.01 | D36: =D35 -> 15336542 | E36: =C36-D36 -> -14746675 | F36: =E36+B36 -> -1.359731e-07

Sheet 2c), 3) Cash Budgets, Y1-Y2
A1: QatarEnergy
A2: Cash Budget
A3: For the Financial Years Ended Dec 31
B5: Y1 | N5: Y2
B6: Jan | C6: Feb | D6: Mar | E6: Apr | F6: May | G6: Jun | H6: Jul | I6: Aug | J6: Sep | K6: Oct | L6: Nov | M6: Dec | N6: Jan | O6: Feb | P6: Mar | Q6: Apr | R6: May | S6: Jun | T6: Jul | U6: Aug | V6: Sep | W6: Oct | X6: Nov | Y6: Dec
A7: Opening Cash | B7: ='2a), 4) Inputs'!B20 -> 0 | C7: =B32 -> 10000000 | D7: =C32 -> 10000000 | E7: =D32 -> 10000000 | F7: =E32 -> 10000000 | G7: =F32 -> 10000000 | H7: =G32 -> 10000000 | I7: =H32 -> 10000000 | J7: =I32 -> 10000000 | ... Y7: =X32 -> 1.512569e+08
A9: CASH INFLOWS
A10: Bank Loan | B10: =MAX(0,(B29+'2a), 4) Inputs'!$B$19)-B7) -> 30833333 | C10: =MAX(0,(C29+'2a), 4) Inputs'!$B$19)-C7) -> 20833333 | D10: =MAX(0,(D29+'2a), 4) Inputs'!$B$19)-D7) -> 20833333 | E10: =MAX(0,(E29+'2a), 4) Inputs'!$B$19)-E7) -> 20833333 | F10: =MAX(0,(F29+'2a), 4) Inputs'!$B$19)-F7) -> 20833333 | G10: =MAX(0,(G29+'2a), 4) Inputs'!$B$19)-G7) -> 20833333 | H10: =MAX(0,(H29+'2a), 4) Inputs'!$B$19)-H7) -> 20833333 | I10: =MAX(0,(I29+'2a), 4) Inputs'!$B$19)-I7) -> 20833333 | ... M10: =MAX(0,(M29+'2a), 4) Inputs'!$B$19)-M7) -> 20833333
A11: Revenue | B11: ='2a), 4) Inputs'!$E$6*'2a), 4) Inputs'!$E$26 -> 0 | C11: ='2a), 4) Inputs'!$E$6*'2a), 4) Inputs'!$E$26 -> 0 | D11: ='2a), 4) Inputs'!$E$6*'2a), 4) Inputs'!$E$26 -> 0 | E11: ='2a), 4) Inputs'!$E$6*'2a), 4) Inputs'!$E$26 -> 0 | F11: ='2a), 4) Inputs'!$E$6*'2a), 4) Inputs'!$E$26 -> 0 | G11: ='2a), 4) Inputs'!$E$6*'2a), 4) Inputs'!$E$26 -> 0 | H11: ='2a), 4) Inputs'!$E$6*'2a), 4) Inputs'!$E$26 -> 0 | I11: ='2a), 4) Inputs'!$E$6*'2a), 4) Inputs'!$E$26 -> 0 | ... M11: ='2a), 4) Inputs'!$E$6*'2a), 4) Inputs'!$E$26 -> 0 | N11: =_xlfn.XLOOKUP(N6,'2b) Schedules'!$H$24:$H$35,'2b) Schedules'!$J$24:$J$35)-(Daily_demand_LNG_Y2*Selling_price_LNG_Y2) -> 65153183 | O11: =_xlfn.XLOOKUP(O6,'2b) Schedules'!$H$24:$H$35,'2b) Schedules'!$J$24:$J$35) -> 61352580 | P11: =_xlfn.XLOOKUP(P6,'2b) Schedules'!$H$24:$H$35,'2b) Schedules'!$J$24:$J$35) -> 67324956 | Q11: =_xlfn.XLOOKUP(Q6,'2b) Schedules'!$H$24:$H$35,'2b) Schedules'!$J$24:$J$35) -> 65153183 | R11: =_xlfn.XLOOKUP(R6,'2b) Schedules'!$H$24:$H$35,'2b) Schedules'!$J$24:$J$35) -> 67324956 | S11: =_xlfn.XLOOKUP(S6,'2b) Schedules'!$H$24:$H$35,'2b) Schedules'!$J$24:$J$35) -> 65153183 | T11: =_xlfn.XLOOKUP(T6,'2b) Schedules'!$H$24:$H$35,'2b) Schedules'!$J$24:$J$35) -> 67324956 | U11: =_xlfn.XLOOKUP(U6,'2b) Schedules'!$H$24:$H$35,'2b) Schedules'!$J$24:$J$35) -> 67324956 | V11: =_xlfn.XLOOKUP(V6,'2b) Schedules'!$H$24:$H$35,'2b) Schedules'!$J$24:$J$35) -> 65153183 | ... Y11: =_xlfn.XLOOKUP(Y6,'2b) Schedules'!$H$24:$H$35,'2b) Schedules'!$J$24:$J$35) -> 67324956
A12: Total Cash Inflows | B12: =SUM(B10:B11) -> 30833333 | C12: =SUM(C10:C11) -> 20833333 | D12: =SUM(D10:D11) -> 20833333 | E12: =SUM(E10:E11) -> 20833333 | F12: =SUM(F10:F11) -> 20833333 | G12: =SUM(G10:G11) -> 20833333 | H12: =SUM(H10:H11) -> 20833333 | I12: =SUM(I10:I11) -> 20833333 | ... Y12: =SUM(Y10:Y11) -> 67324956
A14: CASH OUTFLOWS
